<?xml version="1.0"?>
<robot name="DFRobot" xmlns:xacro="http://www.ros.org/wiki/xacro">

  <link name="base_link"/>

  <joint name="left_wheel_joint" type="continuous">
    <parent link="base_link"/>
    <child link="left_wheel_link"/>
    <origin xyz="0 0.044 0" rpy="0 0 0"/>
    <axis xyz="0 1 0"/>
  </joint>

  <link name="left_wheel_link"/>

  <joint name="right_wheel_joint" type="continuous">
    <parent link="base_link"/>
    <child link="right_wheel_link"/>
    <origin xyz="0 -0.044 0" rpy="0 0 0"/>
    <axis xyz="0 1 0"/>
  </joint>

  <link name="right_wheel_link"/>

<ros2_control name="L298NSystem" type="system">
  <hardware>
    <plugin>l298n_hardware/L298NSystem</plugin>

    <param name="left_pwm_pin">12</param>
    <param name="left_dir1_pin">23</param>
    <param name="left_dir2_pin">24</param>

    <param name="right_pwm_pin">13</param>
    <param name="right_dir1_pin">22</param>
    <param name="right_dir2_pin">27</param>

    <param name="max_wheel_rad_s">11.0</param>
  </hardware>

  <joint name="left_wheel_joint">
    <command_interface name="velocity"/>
    <state_interface name="velocity"/>
  </joint>

  <joint name="right_wheel_joint">
    <command_interface name="velocity"/>
    <state_interface name="velocity"/>
  </joint>
</ros2_control>

</robot>
